Workbook
Name ColumnTitle1: 'FACTURA NOTARÍA'!$B$12
Name ColumnTitle1: 'Póliza de seguro'!$B$13
Name ColumnTitle1: #REF!
Name ColumnTitleRegion1..B11.1: 'FACTURA NOTARÍA'!$B$6
Name ColumnTitleRegion1..B11.1: 'FACTURA VODAFONE'!$B$6
Name ColumnTitleRegion1..B11.1: 'Póliza de seguro'!$B$6
Name ColumnTitleRegion1..B11.1: 'ALQUILER LOCAL'!$B$6
Name Company_Name: 'FACTURA NOTARÍA'!$B$1
Name Company_Name: '[1]CARGO FINANCIERO'!$B$2
Name Company_Name: 'Póliza de seguro'!$B$1
Name Company_Name: 'ALQUILER LOCAL'!$B$1
Name Fecha_Extracto: 'factura trámite'!$F$2
Name Identificador_Cliente: 'factura trámite'!$C$11
Name Importe_Envío: 'factura trámite'!#REF!
Name Nombre_Cliente: 'factura trámite'!$F$9
Name Nombre_de_la_compañía: 'FACTURA GAS'!$B$2
Name Nombre_de_la_compañía: 'FACTURA LUZ '!$B$2
Name Nombre_empresa: 'FACTURA VODAFONE'!$B$1
Name Nombre_empresa: 'FACTURA M.M'!$B$2
Name Número_Extracto: 'factura trámite'!$C$9
Name RegiónDeTítuloDeFila1..E5: 'FACTURA NOTARÍA'!#REF!
Name RegiónDeTítuloDeFila1..E5: 'Póliza de seguro'!#REF!
Name RegiónDeTítuloDeFila1..E5: 'ALQUILER LOCAL'!$D$3
Name RegiónTítulo1..D14: 'FACTURA M.M'!#REF!
Name RegiónTítuloColumna1..B12.1: 'FACTURA M.M'!$B$7
Name RegiónTítuloColumna2..E12.1: 'FACTURA M.M'!$D$7
Name RegiónTítuloFila1..C4: TALLER!$C$1
Name RegiónTítuloFila1..D8: 'FACTURA GAS'!$C$2
Name RegiónTítuloFila1..D8: 'FACTURA LUZ '!$C$2
Name RegiónTítuloFila1..E5: 'FACTURA M.M'!$D$3
Name RegiónTítuloFila1..F2: TALLER!$E$1
Name RowTitleRegion1..D4.1: '[2]CARGO FINANCIEROE'!$C$2
Name Título1: 'factura trámite'!#REF!
Name TítuloColumna1: 'FACTURA AMAZON'!$B$14
Name TítuloColumna1: Factura7[[#Headers],[DESCRIPCIÓN]]
Name TítuloColumna1: DetallesDeFactura[[#Headers],[DESCRIPCIÓN]]
Name TítuloColumna1: #REF!
Name TítuloColumna1: DetallesDeFactura[[#Headers],[DESCRIPCIÓN]]
Name TítuloColumnaRegión1..B6.1: 'FACTURA AMAZON'!$B$2
Name TítuloColumnaRegión2..B13.1: 'FACTURA AMAZON'!$B$7
Name TítuloDeColumna1: 'FACTURA LUZ '!$B$10
Name TítuloDeColumna1: #REF!
Name TítuloDeColumnaRegión1..C13.1: 'FACTURA IKEA'!$B$8
Name TítuloDeColumnaRegión2..C15.1: 'FACTURA IKEA'!$B$14
Name TítuloDeFilaRegión1..D6: 'FACTURA IKEA'!$C$4
Name TítuloFilaRegión1..D5: 'FACTURA VODAFONE'!$C$3
Name TítuloFilaRegión1..G4: 'factura trámite'!$C$6
Name TítuloFilaRegión2..C8: 'factura trámite'!$B$9
Name Total_Debido: 'factura trámite'!#REF!

Sheet ingresos
C2: 105.8
B3: Prevesión de ventas año 2023
C4: Precio Unitario | D4: enero | E4: febrero | F4: marzo | G4: abril | H4: mayo | I4: junio | J4: julio | K4: agosto | L4: septiembre | M4: octubre | N4: noviembre | O4: diciembre
A5: 25750 | B5: Pase General | C5: 20 | D5: 42 | E5: 50 | F5: 49 | G5: 37 | H5: 25 | I5: 44 | J5: 27 | K5: 41 | L5: 24 | M5: 38 | N5: 46 | O5: 40
A6: 27894 | B6: Entrada grupal ( mínimo 4 pesonas) | C6: 64.99 | D6: 27 | E6: 34 | F6: 43 | G6: 26 | H6: 40 | I6: 23 | J6: 31 | K6: 44 | L6: 34 | M6: 25 | N6: 28 | O6: 25
A7: 23542.69 | B7: Entrada pareja (2 personas) | C7: 44.85025 | D7: 33 | E7: 24 | F7: 29 | G7: 30 | H7: 37 | I7: 31 | J7: 48 | K7: 45 | L7: 45 | M7: 42 | N7: 37 | O7: 35
A8: 20005 | B8: Entrada especial San valentín (2 personas) | C8: 50 | D8: 23 | E8: 24 | F8: 34 | G8: 30 | H8: 47 | I8: 28 | J8: 37 | K8: 31 | L8: 25 | M8: 37 | N8: 24 | O8: 43
A9: 18863.53 | B9: Entrada especial San Valentí (min. 4 personas) | C9: 80 | D9: 25 | E9: 25 | F9: 24 | G9: 46 | H9: 49 | I9: 40 | J9: 43 | K9: 44 | L9: 42 | M9: 23 | N9: 30 | O9: 34
A10: 15461.6 | B10: Entrada especial verano (mín. 4 personas) | C10: 70 | D10: 41 | E10: 40 | F10: 30 | G10: 31 | H10: 38 | I10: 36 | J10: 47 | K10: 41 | L10: 44 | M10: 46 | N10: 33 | O10: 27
A11: 16041.9 | B11: Caja sorpresa | C11: 15.019 | D11: 25 | E11: 49 | F11: 21 | G11: 49 | H11: 25 | I11: 24 | J11: 37 | K11: 41 | L11: 30 | M11: 28 | N11: 41 | O11: 33
A12: 16540 | B12: Entrada especial Halloween (2 personas) | C12: 55 | D12: 24 | E12: 24 | F12: 45 | G12: 23 | H12: 31 | I12: 29 | J12: 24 | K12: 20 | L12: 41 | M12: 29 | N12: 22 | O12: 24
A13: 20840 | B13: Entrada especial Halloween (4 personas) | C13: 100 | D13: 47 | E13: 33 | F13: 40 | G13: 45 | H13: 27 | I13: 27 | J13: 29 | K13: 31 | L13: 30 | M13: 30 | N13: 50 | O13: 49
B14: TOTAL | C14: =SUM(C5:C13) -> 499.85925 | D14: =SUM(D5:D13) -> 287 | E14: =SUM(E5:E13) -> 303 | F14: =SUM(F5:F13) -> 315 | G14: =SUM(G5:G13) -> 317 | H14: =SUM(H5:H13) -> 319 | I14: =SUM(I5:I13) -> 282 | J14: =SUM(J5:J13) -> 323 | ... O14: =SUM(O5:O13) -> 310
C18: enero | D18: febrero | E18: marzo | F18: abril | G18: mayo | H18: junio | I18: julio | J18: agosto | K18: septiembre | L18: octubre | M18: noviembre | N18: diciembre
B19: Pase General | C19: =ingresos!D5*ingresos!$C$5 -> 840 | D19: =ingresos!E5*ingresos!$C$5 -> 1000 | E19: =ingresos!F5*ingresos!$C$5 -> 980 | F19: =ingresos!G5*ingresos!$C$5 -> 740 | G19: =ingresos!H5*ingresos!$C$5 -> 500 | H19: =ingresos!I5*ingresos!$C$5 -> 880 | I19: =ingresos!J5*ingresos!$C$5 -> 540 | J19: =ingresos!K5*ingresos!$C$5 -> 820 | ... N19: =ingresos!O5*ingresos!$C$5 -> 800
B20: Entrada grupal ( mínimo 4 pesonas) | C20: =ingresos!D6*ingresos!$C$6 -> 1754.73 | D20: =ingresos!E6*ingresos!$C$6 -> 2209.66 | E20: =ingresos!F6*ingresos!$C$6 -> 2794.57 | F20: =ingresos!G6*ingresos!$C$6 -> 1689.74 | G20: =ingresos!H6*ingresos!$C$6 -> 2599.6 | H20: =ingresos!I6*ingresos!$C$6 -> 1494.77 | I20: =ingresos!J6*ingresos!$C$6 -> 2014.69 | J20: =ingresos!K6*ingresos!$C$6 -> 2859.56 | ... N20: =ingresos!O6*ingresos!$C$6 -> 1624.75
B21: Entrada pareja (2 personas) | C21: =ingresos!D7*ingresos!$C$7 -> 1480.0583 | D21: =ingresos!E7*ingresos!$C$7 -> 1076.406 | E21: =ingresos!F7*ingresos!$C$7 -> 1300.6572 | F21: =ingresos!G7*ingresos!$C$7 -> 1345.5075 | G21: =ingresos!H7*ingresos!$C$7 -> 1659.4593 | H21: =ingresos!I7*ingresos!$C$7 -> 1390.3578 | I21: =ingresos!J7*ingresos!$C$7 -> 2152.812 | J21: =ingresos!K7*ingresos!$C$7 -> 2018.2613 | ... N21: =ingresos!O7*ingresos!$C$7 -> 1569.7588
B22: Entrada especial San valentín (2 personas) | C22: =ingresos!D8*ingresos!$C$8 -> 1150 | D22: =ingresos!E8*ingresos!$C$8 -> 1200 | E22: =ingresos!F8*ingresos!$C$8 -> 1700 | F22: =ingresos!G8*ingresos!$C$8 -> 1500 | G22: =ingresos!H8*ingresos!$C$8 -> 2350 | H22: =ingresos!I8*ingresos!$C$8 -> 1400 | I22: =ingresos!J8*ingresos!$C$8 -> 1850 | J22: =ingresos!K8*ingresos!$C$8 -> 1550 | ... N22: =ingresos!O8*ingresos!$C$8 -> 2150
B23: Entrada especial San Valentí (min. 4 personas) | C23: =ingresos!D9*ingresos!$C$9 -> 2000 | D23: =ingresos!E9*ingresos!$C$9 -> 2000 | E23: =ingresos!F9*ingresos!$C$9 -> 1920 | F23: =ingresos!G9*ingresos!$C$9 -> 3680 | G23: =ingresos!H9*ingresos!$C$9 -> 3920 | H23: =ingresos!I9*ingresos!$C$9 -> 3200 | I23: =ingresos!J9*ingresos!$C$9 -> 3440 | J23: =ingresos!K9*ingresos!$C$9 -> 3520 | ... N23: =ingresos!O9*ingresos!$C$9 -> 2720
B24: Entrada especial verano (mín. 4 personas) | C24: =ingresos!D10*$C$10 -> 2870 | D24: =ingresos!E10*$C$10 -> 2800 | E24: =ingresos!F10*$C$10 -> 2100 | F24: =ingresos!G10*$C$10 -> 2170 | G24: =ingresos!H10*$C$10 -> 2660 | H24: =ingresos!I10*$C$10 -> 2520 | I24: =ingresos!J10*$C$10 -> 3290 | J24: =ingresos!K10*$C$10 -> 2870 | ... N24: =ingresos!O10*$C$10 -> 1890
B25: Caja sorpresa | C25: =ingresos!D11*ingresos!$C$11 -> 375.475 | D25: =ingresos!E11*ingresos!$C$11 -> 735.931 | E25: =ingresos!F11*ingresos!$C$11 -> 315.399 | F25: =ingresos!G11*ingresos!$C$11 -> 735.931 | G25: =ingresos!H11*ingresos!$C$11 -> 375.475 | H25: =ingresos!I11*ingresos!$C$11 -> 360.456 | I25: =ingresos!J11*ingresos!$C$11 -> 555.703 | J25: =ingresos!K11*ingresos!$C$11 -> 615.779 | ... N25: =ingresos!O11*ingresos!$C$11 -> 495.627
B26: Entrada especial Halloween (2 personas) | C26: =ingresos!D12*ingresos!$C$12 -> 1320 | D26: =ingresos!E12*ingresos!$C$12 -> 1320 | E26: =ingresos!F12*ingresos!$C$12 -> 2475 | F26: =ingresos!G12*ingresos!$C$12 -> 1265 | G26: =ingresos!H12*ingresos!$C$12 -> 1705 | H26: =ingresos!I12*ingresos!$C$12 -> 1595 | I26: =ingresos!J12*ingresos!$C$12 -> 1320 | J26: =ingresos!K12*ingresos!$C$12 -> 1100 | ... N26: =ingresos!O12*ingresos!$C$12 -> 1320
B27: Entrada especial Halloween (4 personas) | C27: =ingresos!D13*$C$13 -> 4700 | D27: =ingresos!E13*$C$13 -> 3300 | E27: =ingresos!F13*$C$13 -> 4000 | F27: =ingresos!G13*$C$13 -> 4500 | G27: =ingresos!H13*$C$13 -> 2700 | H27: =ingresos!I13*$C$13 -> 2700 | I27: =ingresos!J13*$C$13 -> 2900 | J27: =ingresos!K13*$C$13 -> 3100 | ... N27: =ingresos!O13*$C$13 -> 4900
B28: TOTAL | C28: =SUM(C19:C27) -> 16490.263 | D28: =SUM(D19:D27) -> 15641.997 | E28: =SUM(E19:E27) -> 17585.626 | F28: =SUM(F19:F27) -> 17626.179 | G28: =SUM(G19:G27) -> 18469.534 | H28: =SUM(H19:H27) -> 15540.584 | I28: =SUM(I19:I27) -> 18063.205 | J28: =SUM(J19:J27) -> 18453.6 | ... N28: =SUM(N19:N27) -> 17470.136
B29: TOTAL ANUAL | C29: =SUM(C28:N28) -> 206773.57

Sheet Resultados
C5: GASTOS 2022
C6: ENERO | D6: FEBRERO | E6: MARZO | F6: ABRIL | G6: MAYO | H6: JUNIO | I6: JULIO | J6: AGOSTO | K6: SEPTIEMBRE | L6: OCTUBRE | M6: NOVIEMBRE | N6: DICIEMBRE
B8: Canal de Isabel II | C8: ='FACTURA AGUA'!$D$21 -> 103.4 | D8: ='FACTURA AGUA'!$D$21 -> 103.4 | E8: ='FACTURA AGUA'!$D$21 -> 103.4 | F8: ='FACTURA AGUA'!$D$21 -> 103.4 | G8: ='FACTURA AGUA'!$D$21 -> 103.4 | H8: ='FACTURA AGUA'!$D$21 -> 103.4 | I8: ='FACTURA AGUA'!$D$21 -> 103.4 | J8: ='FACTURA AGUA'!$D$21 -> 103.4 | ... N8: ='FACTURA AGUA'!$D$21 -> 103.4 | O8: =SUM(C8:N8) -> 1240.8 | P8: 913.08
B9: Iberdrola | C9: ='FACTURA LUZ '!$D$13+'FACTURA GAS'!$D$13 -> 403.81 | D9: ='FACTURA LUZ '!$D$13+'FACTURA GAS'!$D$13 -> 403.81 | E9: ='FACTURA LUZ '!$D$13+'FACTURA GAS'!$D$13 -> 403.81 | F9: ='FACTURA LUZ '!$D$13+'FACTURA GAS'!$D$13 -> 403.81 | G9: ='FACTURA LUZ '!$D$13+'FACTURA GAS'!$D$13 -> 403.81 | H9: ='FACTURA LUZ '!$D$13+'FACTURA GAS'!$D$13 -> 403.81 | I9: ='FACTURA LUZ '!$D$13+'FACTURA GAS'!$D$13 -> 403.81 | J9: ='FACTURA LUZ '!$D$13+'FACTURA GAS'!$D$13 -> 403.81 | ... N9: ='FACTURA LUZ '!$D$13+'FACTURA GAS'!$D$13 -> 403.81 | O9: =SUM(C9:N9) -> 4845.72 | P9: 4845.7596
B10: Vodafone | C10: ='FACTURA VODAFONE'!$D$16 -> 120.25 | D10: ='FACTURA VODAFONE'!$D$16 -> 120.25 | E10: ='FACTURA VODAFONE'!$D$16 -> 120.25 | F10: ='FACTURA VODAFONE'!$D$16 -> 120.25 | G10: ='FACTURA VODAFONE'!$D$16 -> 120.25 | H10: ='FACTURA VODAFONE'!$D$16 -> 120.25 | I10: ='FACTURA VODAFONE'!$D$16 -> 120.25 | J10: ='FACTURA VODAFONE'!$D$16 -> 120.25 | ... N10: ='FACTURA VODAFONE'!$D$16 -> 120.25 | O10: =SUM(C10:N10) -> 1443 | P10: 1190.64
C11: ARRENDAMIENTOS | O11: =SUM(C11:N11) -> 0 | P11: 0
B12: Alquiler nave | C12: ='ALQUILER LOCAL'!$C$15 -> 4500 | D12: ='ALQUILER LOCAL'!$C$15 -> 4500 | E12: ='ALQUILER LOCAL'!$C$15 -> 4500 | F12: ='ALQUILER LOCAL'!$C$15 -> 4500 | G12: ='ALQUILER LOCAL'!$C$15 -> 4500 | H12: ='ALQUILER LOCAL'!$C$15 -> 4500 | I12: ='ALQUILER LOCAL'!$C$15 -> 4500 | J12: ='ALQUILER LOCAL'!$C$15 -> 4500 | ... N12: ='ALQUILER LOCAL'!$C$15 -> 4500 | O12: =SUM(C12:N12) -> 54000 | P12: 18360
C13: GASTOS DE PERSONAL | O13: =SUM(C13:N13) -> 0 | P13: 0
B14: Sueldos y salarios | C14: ='Cálculos Nómina'!C10 -> 7690.5 | D14: ='Cálculos Nómina'!$C$10 -> 7690.5 | E14: ='Cálculos Nómina'!$C$10 -> 7690.5 | F14: ='Cálculos Nómina'!$C$10 -> 7690.5 | G14: ='Cálculos Nómina'!$C$10 -> 7690.5 | H14: ='Cálculos Nómina'!$C$10 -> 7690.5 | I14: ='Cálculos Nómina'!$C$10 -> 7690.5 | J14: ='Cálculos Nómina'!$C$10 -> 7690.5 | K14: ='Cálculos Nómina'!$C$10 -> 7690.5 | ... N14: ='Cálculos Nómina'!$C$10 -> 7690.5 | O14: =SUM(C14:N14) -> 92286 | P14: 101928.04 | Q14: =O14+O15 -> 102618.74
B15: Seguridad social c/e | C15: ='Cálculos Nómina'!C20 -> 861.06206 | D15: ='Cálculos Nómina'!$C$20 -> 861.06206 | E15: ='Cálculos Nómina'!$C$20 -> 861.06206 | F15: ='Cálculos Nómina'!$C$20 -> 861.06206 | G15: ='Cálculos Nómina'!$C$20 -> 861.06206 | H15: ='Cálculos Nómina'!$C$20 -> 861.06206 | I15: ='Cálculos Nómina'!$C$20 -> 861.06206 | J15: ='Cálculos Nómina'!$C$20 -> 861.06206 | K15: ='Cálculos Nómina'!$C$20 -> 861.06206 | ... N15: ='Cálculos Nómina'!$C$20 -> 861.06206 | O15: =SUM(C15:N15) -> 10332.745 | P15: 15400.134 | Q15: =P14+P15+P28 -> 120028.17
C16: SERVICIOS EXTERNOS | O16: =SUM(C16:N16) -> 0 | P16: 0
B17: Prima de seguros | C17: ='Póliza de seguro'!$C$17 -> 615.3 | D17: ='Póliza de seguro'!$C$17 -> 615.3 | E17: ='Póliza de seguro'!$C$17 -> 615.3 | F17: ='Póliza de seguro'!$C$17 -> 615.3 | G17: ='Póliza de seguro'!$C$17 -> 615.3 | H17: ='Póliza de seguro'!$C$17 -> 615.3 | I17: ='Póliza de seguro'!$C$17 -> 615.3 | J17: ='Póliza de seguro'!$C$17 -> 615.3 | ... N17: ='Póliza de seguro'!$C$17 -> 615.3 | O17: =SUM(C17:N17) -> 7383.6 | P17: 7383.6
C18: AMORTIZACIONES | O18: =SUM(C18:N18) -> 0 | P18: 0
C19: INTANGIBLE | O19: =SUM(C19:N19) -> 0 | P19: 561.28
B20: Aplicaciones informáticas | C20: ='INVERSIÓN Y AMORT.'!$H$14 -> 9.3546667 | D20: ='INVERSIÓN Y AMORT.'!$H$14 -> 9.3546667 | E20: ='INVERSIÓN Y AMORT.'!$H$14 -> 9.3546667 | F20: ='INVERSIÓN Y AMORT.'!$H$14 -> 9.3546667 | G20: ='INVERSIÓN Y AMORT.'!$H$14 -> 9.3546667 | H20: ='INVERSIÓN Y AMORT.'!$H$14 -> 9.3546667 | I20: ='INVERSIÓN Y AMORT.'!$H$14 -> 9.3546667 | J20: ='INVERSIÓN Y AMORT.'!$H$14 -> 9.3546667 | ... N20: ='INVERSIÓN Y AMORT.'!$H$14 -> 9.3546667 | O20: =SUM(C20:N20) -> 112.256 | P20: 3500
C21: MATERIAL | O21: =SUM(C21:N21) -> 0 | P21: 294.95
B22: Equipos para el proceso de información | C22: ='INVERSIÓN Y AMORT.'!$H$19 -> 9.125 | D22: ='INVERSIÓN Y AMORT.'!$H$19 -> 9.125 | E22: ='INVERSIÓN Y AMORT.'!$H$19 -> 9.125 | F22: ='INVERSIÓN Y AMORT.'!$H$19 -> 9.125 | G22: ='INVERSIÓN Y AMORT.'!$H$19 -> 9.125 | H22: ='INVERSIÓN Y AMORT.'!$H$19 -> 9.125 | I22: ='INVERSIÓN Y AMORT.'!$H$19 -> 9.125 | J22: ='INVERSIÓN Y AMORT.'!$H$19 -> 9.125 | ... N22: ='INVERSIÓN Y AMORT.'!$H$19 -> 9.125 | O22: =SUM(C22:N22) -> 109.5 | P22: 2580
B23: Otro inmovilizado material | C23: ='INVERSIÓN Y AMORT.'!$H$20 -> 2.5825 | D23: ='INVERSIÓN Y AMORT.'!$H$20 -> 2.5825 | E23: ='INVERSIÓN Y AMORT.'!$H$20 -> 2.5825 | F23: ='INVERSIÓN Y AMORT.'!$H$20 -> 2.5825 | G23: ='INVERSIÓN Y AMORT.'!$H$20 -> 2.5825 | H23: ='INVERSIÓN Y AMORT.'!$H$20 -> 2.5825 | I23: ='INVERSIÓN Y AMORT.'!$H$20 -> 2.5825 | J23: ='INVERSIÓN Y AMORT.'!$H$20 -> 2.5825 | ... N23: ='INVERSIÓN Y AMORT.'!$H$20 -> 2.5825 | O23: =SUM(C23:N23) -> 30.99 | P23: 184938.72
B24: Otras instalaciones | C24: ='INVERSIÓN Y AMORT.'!$H$21 -> 7.9343452 | D24: ='INVERSIÓN Y AMORT.'!$H$21 -> 7.9343452 | E24: ='INVERSIÓN Y AMORT.'!$H$21 -> 7.9343452 | F24: ='INVERSIÓN Y AMORT.'!$H$21 -> 7.9343452 | G24: ='INVERSIÓN Y AMORT.'!$H$21 -> 7.9343452 | H24: ='INVERSIÓN Y AMORT.'!$H$21 -> 7.9343452 | I24: ='INVERSIÓN Y AMORT.'!$H$21 -> 7.9343452 | J24: ='INVERSIÓN Y AMORT.'!$H$21 -> 7.9343452 | ... N24: ='INVERSIÓN Y AMORT.'!$H$21 -> 7.9343452 | O24: =SUM(C24:N24) -> 95.212143 | P24: 4522.7
B25: Mobiliario | C25: ='INVERSIÓN Y AMORT.'!$H$18 -> 11.889062 | D25: ='INVERSIÓN Y AMORT.'!$H$18 -> 11.889062 | E25: ='INVERSIÓN Y AMORT.'!$H$18 -> 11.889062 | F25: ='INVERSIÓN Y AMORT.'!$H$18 -> 11.889062 | G25: ='INVERSIÓN Y AMORT.'!$H$18 -> 11.889062 | H25: ='INVERSIÓN Y AMORT.'!$H$18 -> 11.889062 | I25: ='INVERSIÓN Y AMORT.'!$H$18 -> 11.889062 | J25: ='INVERSIÓN Y AMORT.'!$H$18 -> 11.889062 | ... N25: ='INVERSIÓN Y AMORT.'!$H$18 -> 11.889062 | O25: =SUM(C25:N25) -> 142.66875 | P25: 585
C26: SERVICIOS PROFESIONALES INDEPENDIENTES | O26: =SUM(C26:N26) -> 0 | P26: 105.8
B27: Notario | C27: ='FACTURA NOTARÍA'!$C$14 -> 105.8 | D27: 0 | E27: 0 | F27: 0 | G27: 0 | H27: 0 | I27: 0 | J27: 0 | K27: 0 | L27: 0 | M27: 0 | N27: 0 | O27: =SUM(C27:N27) -> 105.8 | P27: 1660.9839
B28: Trámite | C28: ='factura trámite'!$E$16 -> 350 | D28: 0 | E28: 0 | F28: 0 | G28: 0 | H28: 0 | I28: 0 | J28: 0 | K28: 0 | L28: 0 | M28: 0 | N28: 0 | O28: =SUM(C28:N28) -> 350 | P28: 2700
B30: GASTOS TOTALES | C30: =SUM(C8:C28) -> 14791.008 | D30: =SUM(D8:D28) -> 14335.208 | E30: =SUM(E8:E28) -> 14335.208 | F30: =SUM(F8:F28) -> 14335.208 | G30: =SUM(G8:G28) -> 14335.208 | H30: =SUM(H8:H28) -> 14335.208 | I30: =SUM(I8:I28) -> 14335.208 | J30: =SUM(J8:J28) -> 14335.208 | ... N30: =SUM(N8:N28) -> 14335.208
B31: TOTAL | C31: =SUM(C30:N30) -> 172478.29
C33: INGRESOS
C34: ENERO | D34: FEBRERO | E34: MARZO | F34: ABRIL | G34: MAYO | H34: JUNIO | I34: JULIO | J34: AGOSTO | K34: SEPTIEMBRE | L34: OCTUBRE | M34: NOVIEMBRE | N34: DICIEMBRE
B36: Ingresos | C36: =ingresos!C28 -> 16490.263 | D36: =ingresos!D28 -> 15641.997 | E36: =ingresos!E28 -> 17585.626 | F36: =ingresos!F28 -> 17626.179 | G36: =ingresos!G28 -> 18469.534 | H36: =ingresos!H28 -> 15540.584 | I36: =ingresos!I28 -> 18063.205 | J36: =ingresos!J28 -> 18453.6 | ... N36: =ingresos!N28 -> 17470.136 | O36: =SUM(C36:N36) -> 206773.57
B38: INGRESOS TOTALES | C38: =SUM(C36:N36) -> 206773.57
C42: RESULTADOS 2022
C43: ENERO | D43: FEBRERO | E43: MARZO | F43: ABRIL | G43: MAYO | H43: JUNIO | I43: JULIO | J43: AGOSTO | K43: SEPTIEMBRE | L43: OCTUBRE | M43: NOVIEMBRE | N43: DICIEMBRE | O43: Resultado TOTAL | P43: Impuesto Sociedades | Q43: Beneficio Neto
B45: Diferencia | C45: =C36-C30 -> 1699.2556 | D45: =D36-D30 -> 1306.7894 | E45: =E36-E30 -> 3250.4186 | F45: =F36-F30 -> 3290.9709 | G45: =G36-G30 -> 4134.3266 | H45: =H36-H30 -> 1205.3761 | I45: =I36-I30 -> 3727.9974 | J45: =J36-J30 -> 4118.3926 | ... N45: =N36-N30 -> 3134.9281 | O45: =SUM(C45:N45) -> 34295.274 | P45: =O45*0.25 -> 8573.8186 | Q45: =O45-P45 -> 25721.456
B51: Resultado

Sheet TESORERÍA
C5: PAGOS
C6: ENERO | D6: FEBRERO | E6: MARZO | F6: ABRIL | G6: MAYO | H6: JUNIO | I6: JULIO | J6: AGOSTO | K6: SEPTIEMBRE | L6: OCTUBRE | M6: NOVIEMBRE | N6: DICIEMBRE
C7: 1 | D7: 2 | E7: 1 | F7: 2 | G7: 1 | H7: 2 | I7: 1 | J7: 2 | K7: 1 | L7: 2 | M7: 1 | N7: 2
O8: =SUM(C8:N8) -> 0
B9: Canal de Isabel II | C9: =IF(TESORERÍA!B7:M7=2,'FACTURA AGUA'!$D$21*2,"") | D9: =Resultados!C8+Resultados!D8 -> 206.8 | E9: =IF(TESORERÍA!D7:O7=2,'FACTURA AGUA'!$D$21*2,"") | F9: =IF(TESORERÍA!E7:P7=2,'FACTURA AGUA'!$D$21*2,"") -> 206.8 | G9: =IF(TESORERÍA!F7:Q7=2,'FACTURA AGUA'!$D$21*2,"") | H9: =IF(TESORERÍA!G7:R7=2,'FACTURA AGUA'!$D$21*2,"") -> 206.8 | I9: =IF(TESORERÍA!H7:S7=2,'FACTURA AGUA'!$D$21*2,"") | J9: =IF(TESORERÍA!I7:T7=2,'FACTURA AGUA'!$D$21*2,"") -> 206.8 | K9: =IF(TESORERÍA!J7:U7=2,'FACTURA AGUA'!$D$21*2,"") | L9: =IF(TESORERÍA!K7:V7=2,'FACTURA AGUA'!$D$21*2,"") -> 206.8 | ... N9: =IF(TESORERÍA!M7:X7=2,'FACTURA AGUA'!$D$21*2,"") -> 206.8 | O9: =SUM(C9:N9) -> 1240.8
B10: Iberdrola | C10: =Resultados!C9 -> 403.81 | D10: =Resultados!D9 -> 403.81 | E10: =Resultados!E9 -> 403.81 | F10: =Resultados!F9 -> 403.81 | G10: =Resultados!G9 -> 403.81 | H10: =Resultados!H9 -> 403.81 | I10: =Resultados!I9 -> 403.81 | J10: =Resultados!J9 -> 403.81 | ... O10: =Resultados!O9 -> 4845.72
B11: Vodafone | C11: =Resultados!C10 -> 120.25 | D11: =Resultados!D10 -> 120.25 | E11: =Resultados!E10 -> 120.25 | F11: =Resultados!F10 -> 120.25 | G11: =Resultados!G10 -> 120.25 | H11: =Resultados!H10 -> 120.25 | I11: =Resultados!I10 -> 120.25 | J11: =Resultados!J10 -> 120.25 | ... O11: =Resultados!O10 -> 1443
O12: =SUM(C12:N12) -> 0
B13: Alquiler nave | C13: =Resultados!C12 -> 4500 | D13: =Resultados!D12 -> 4500 | E13: =Resultados!E12 -> 4500 | F13: =Resultados!F12 -> 4500 | G13: =Resultados!G12 -> 4500 | H13: =Resultados!H12 -> 4500 | I13: =Resultados!I12 -> 4500 | J13: =Resultados!J12 -> 4500 | ... N13: =Resultados!N12 -> 4500 | O13: =SUM(C13:N13) -> 54000
O14: =SUM(C14:N14) -> 0
B15: Sueldos y salarios | C15: ='Cálculos Nómina'!$F$10 -> 7102.2225 | D15: ='Cálculos Nómina'!$F$10 -> 7102.2225 | E15: ='Cálculos Nómina'!$F$10 -> 7102.2225 | F15: ='Cálculos Nómina'!$F$10 -> 7102.2225 | G15: ='Cálculos Nómina'!$F$10 -> 7102.2225 | H15: ='Cálculos Nómina'!$F$10 -> 7102.2225 | I15: ='Cálculos Nómina'!$F$10 -> 7102.2225 | J15: ='Cálculos Nómina'!$F$10 -> 7102.2225 | ... N15: ='Cálculos Nómina'!$F$10 -> 7102.2225 | O15: =SUM(C15:N15) -> 85226.67
B16: Seguros sociales | D16: ='Cálculos Nómina'!$E$20 -> 1049.3396 | E16: ='Cálculos Nómina'!$E$20 -> 1049.3396 | F16: ='Cálculos Nómina'!$E$20 -> 1049.3396 | G16: ='Cálculos Nómina'!$E$20 -> 1049.3396 | H16: ='Cálculos Nómina'!$E$20 -> 1049.3396 | I16: ='Cálculos Nómina'!$E$20 -> 1049.3396 | J16: ='Cálculos Nómina'!$E$20 -> 1049.3396 | K16: ='Cálculos Nómina'!$E$20 -> 1049.3396 | ... N16: ='Cálculos Nómina'!$E$20 -> 1049.3396 | O16: =SUM(C16:N16) -> 11542.735
O17: =SUM(C17:N17) -> 0
B18: Prima de seguros | C18: =Resultados!C17 -> 615.3 | D18: =Resultados!D17 -> 615.3 | E18: =Resultados!E17 -> 615.3 | F18: =Resultados!F17 -> 615.3 | G18: =Resultados!G17 -> 615.3 | H18: =Resultados!H17 -> 615.3 | I18: =Resultados!I17 -> 615.3 | J18: =Resultados!J17 -> 615.3 | ... N18: =Resultados!N17 -> 615.3 | O18: =SUM(C18:N18) -> 7383.6
O19: =SUM(C19:N19) -> 0
B20: Aplicaciones informáticas | C20: ='INVERSIÓN Y AMORT.'!$C$5 -> 561.28 | O20: =SUM(C20:N20) -> 561.28
B21: Equipos para el proceso de información | C21: ='INVERSIÓN Y AMORT.'!$C$7 -> 1095 | O21: =SUM(C21:N21) -> 1095
B22: Otro inmovilizado material | C22: ='INVERSIÓN Y AMORT.'!$C$8 -> 154.95 | O22: =SUM(C22:N22) -> 154.95
B23: Otras instalaciones | C23: ='INVERSIÓN Y AMORT.'!$C$9 -> 1332.97 | O23: =SUM(C23:N23) -> 1332.97
B24: Mobiliario | C24: ='INVERSIÓN Y AMORT.'!$C$6 -> 2282.7 | O24: =SUM(C24:N24) -> 2282.7
O25: =SUM(C25:N25) -> 0
B26: Notario | C26: =Resultados!C27 -> 105.8 | D26: =Resultados!D27 -> 0 | E26: =Resultados!E27 -> 0 | F26: =Resultados!F27 -> 0 | G26: =Resultados!G27 -> 0 | H26: =Resultados!H27 -> 0 | I26: =Resultados!I27 -> 0 | J26: =Resultados!J27 -> 0 | ... N26: =Resultados!N27 -> 0 | O26: =SUM(C26:N26) -> 105.8
B27: Trámite | C27: =Resultados!C28 -> 350 | D27: =Resultados!D28 -> 0 | E27: =Resultados!E28 -> 0 | F27: =Resultados!F28 -> 0 | G27: =Resultados!G28 -> 0 | H27: =Resultados!H28 -> 0 | I27: =Resultados!I28 -> 0 | J27: =Resultados!J28 -> 0 | ... N27: =Resultados!N28 -> 0 | O27: =SUM(C27:N27) -> 350
B28: Hp Iva | F28: ='I.V.A'!$C$26 -> 6095.5684 | I28: ='I.V.A'!$E$26 -> 7597.7025 | L28: ='I.V.A'!$G$26 -> 8264.7235 | O28: =SUM(C28:N28) -> 21957.994
B29: Retención | C29: =-0.19*$G$13 -> -855 | D29: =-0.19*$G$13 -> -855 | E29: =-0.19*$G$13 -> -855 | F29: =-0.19*$G$13 -> -855 | G29: =-0.19*$G$13 -> -855 | H29: =-0.19*$G$13 -> -855 | I29: =-0.19*$G$13 -> -855 | J29: =-0.19*$G$13 -> -855 | ... O29: =-0.19*$G$13 -> -855
B30: Ret. Irpf Alquiler ( modelo 115) | F30: =3*(0.19*C13) -> 2565 | I30: =3*($C$13*0.19) -> 2565 | L30: =3*($E$13*0.19) -> 2565 | O30: =SUM(C30:M30) -> 7695
B31: HP IRPF (modelo 111) | F31: ='Cálculos Nómina'!$E$10*3 -> 1200 | I31: ='Cálculos Nómina'!$E$10*3 -> 1200 | L31: ='Cálculos Nómina'!$E$10*3 -> 1200
B32: PAGOS TOTALES | C32: =SUM(C9:C31) -> 17769.283 | D32: =SUM(D9:D31) -> 13142.722 | E32: =SUM(E9:E31) -> 12935.922 | F32: =SUM(F9:F31) -> 23003.29 | G32: =SUM(G9:G31) -> 12935.922 | H32: =SUM(H9:H31) -> 13142.722 | I32: =SUM(I9:I31) -> 24298.625 | J32: =SUM(J9:J31) -> 13142.722 | ... O32: =SUM(O9:O31) -> 200363.22 | P32: =SUM(C32:N32) -> 194558.22
B33: Base Impoible AL 21% | C33: =SUM(C10:C13)+SUM(C20:C25) -> 10450.96 | D33: =SUM(D10:D13)+SUM(D20:D25) -> 5024.06 | E33: =SUM(E10:E13)+SUM(E20:E25) -> 5024.06 | F33: =SUM(F10:F13)+SUM(F20:F25) -> 5024.06 | G33: =SUM(G10:G13)+SUM(G20:G25) -> 5024.06 | H33: =SUM(H10:H13)+SUM(H20:H25) -> 5024.06 | I33: =SUM(I10:I13)+SUM(I20:I25) -> 5024.06 | J33: =SUM(J10:J13)+SUM(J20:J25) -> 5024.06 | ... O33: =SUM(O10:O13)+SUM(O20:O25) -> 65715.62
B34: Base Impoible AL 10% | C34: =IF(C9>0,C9,"") | D34: =IF(D9>0,D9,"") -> 206.8 | E34: =IF(E9>0,E9,"") | F34: =IF(F9>0,F9,"") -> 206.8 | G34: =IF(G9>0,G9,"") | H34: =IF(H9>0,H9,"") -> 206.8 | I34: =IF(I9>0,I9,"") | J34: =IF(J9>0,J9,"") -> 206.8 | ... N34: =IF(N9>0,N9,"") -> 206.8 | O34: =O9 -> 1240.8
B35: I.V.A 21% | C35: =C33*0.21 -> 2194.7016 | D35: =D33*0.21 -> 1055.0526 | E35: =E33*0.21 -> 1055.0526 | F35: =F33*0.21 -> 1055.0526 | G35: =G33*0.21 -> 1055.0526 | H35: =H33*0.21 -> 1055.0526 | I35: =I33*0.21 -> 1055.0526 | J35: =J33*0.21 -> 1055.0526 | ... N35: =N33*0.21 -> 1055.0526 | O35: =SUM(C35:N35) -> 13800.28
B36: I.V.A 10% | D36: =0.1*C10 -> 40.381 | F36: =0.1*E10 -> 40.381 | H36: =0.1*G10 -> 40.381 | J36: =0.1*I10 -> 40.381 | L36: =0.1*K10 -> 40.381 | N36: =0.1*M10 -> 40.381
B37: TOTAL + IVA | C37: =C32+C35+C36 -> 19963.984 | D37: =D32+D35+D36 -> 14238.156 | E37: =E32+E35+E36 -> 13990.975 | F37: =F32+F35+F36 -> 24098.724 | G37: =G32+G35+G36 -> 13990.975 | H37: =H32+H35+H36 -> 14238.156 | I37: =I32+I35+I36 -> 25353.677 | J37: =J32+J35+J36 -> 14238.156 | ... N37: =N32+N35+N36 -> 14238.156 | O37: =SUM(C37:N37) -> 208600.79
C40: COBROS
C41: ENERO | D41: FEBRERO | E41: MARZO | F41: ABRIL | G41: MAYO | H41: JUNIO | I41: JULIO | J41: AGOSTO | K41: SEPTIEMBRE | L41: OCTUBRE | M41: NOVIEMBRE | N41: DICIEMBRE
B42: CONCEPTO
B43: Total ventas | C43: =Resultados!C36 -> 16490.263 | D43: =Resultados!D36 -> 15641.997 | E43: =Resultados!E36 -> 17585.626 | F43: =Resultados!F36 -> 17626.179 | G43: =Resultados!G36 -> 18469.534 | H43: =Resultados!H36 -> 15540.584 | I43: =Resultados!I36 -> 18063.205 | J43: =Resultados!J36 -> 18453.6 | ... N43: =Resultados!N36 -> 17470.136 | O43: =SUM(C43:N43) -> 206773.57
B44: Aportación socios | C44: 25000
B47: Cobros totales | C47: =SUM(C43:C44) -> 41490.263 | D47: =SUM(D43:D44) -> 15641.997 | E47: =SUM(E43:E44) -> 17585.626 | F47: =SUM(F43:F44) -> 17626.179 | G47: =SUM(G43:G44) -> 18469.534 | H47: =SUM(H43:H44) -> 15540.584 | I47: =SUM(I43:I44) -> 18063.205 | J47: =SUM(J43:J44) -> 18453.6 | ... N47: =SUM(N43:N44) -> 17470.136 | O47: =SUM(C47:N47) -> 231773.57
B48: I.V.A REPERCUTIDO | C48: =C43*0.21 -> 3462.9553 | D48: =D43*0.21 -> 3284.8194 | E48: =E43*0.21 -> 3692.9815 | F48: =F43*0.21 -> 3701.4975 | G48: =G43*0.21 -> 3878.6022 | H48: =H43*0.21 -> 3263.5226 | I48: =I43*0.21 -> 3793.2731 | J48: =J43*0.21 -> 3875.2561 | ... N48: =N43*0.21 -> 3668.7285 | O48: =SUM(C48:N48) -> 43422.449
...

Sheet INVERSIÓN Y AMORT.
B3: PLAN DE INVERSIÓN
B4: ELEMENTOS | C4: CUANTÍA
B5: APLICACIONES INFORMÁTICAS | C5: =('FACTURA AMAZON'!$C$16+'FACTURA AMAZON'!$C$18) -> 561.28 | D5: Son office y aplifisa
B6: MOBILIARIO | C6: ='FACTURA IKEA'!$E$38 -> 2282.7 | D6: todo lo de ikea
B7: EQUIPOS PARA EL PROCESO DE INFORMACIÓN | C7: ='FACTURA M.M'!E14+'FACTURA M.M'!E15+'FACTURA M.M'!E20+'FACTURA M.M'!E21 -> 1095 | D7: ordenadores, televisores, impresoras, proyector, etc…
B8: OTRO INMOVILIZADO MATERIAL | C8: =('FACTURA M.M'!$E$16+'FACTURA AMAZON'!$C$15) -> 154.95 | D8: extintores, telefono fijo
B9: OTRAS INSTALACIONES | C9: ='FACTURA M.M'!$E$17+'FACTURA M.M'!$E$18 -> 1332.97 | D9: aire acondicionado, alarma de seguridad
C10: =SUM(C5:C9) -> 5426.9
D13: INMOVILIZADO INTANGIBLE | E13: Valor | F13: Periodo (años) | G13: Cuota anual | H13: Cuota mensual
D14: APLICACIONES INFORMÁTICAS | E14: =$C$5 -> 561.28 | F14: 5 | G14: =$E$14/$F$14 -> 112.256 | H14: =$G$14/12 -> 9.3546667
E15: Amortización intangible | G15: =$G$14 -> 112.256 | H15: =$H$14 -> 9.3546667
D17: INMOVILIZADO MATERIAL | E17: Valor | F17: Periodo (años) | G17: Cuota anual | H17: Cuota mensual
D18: MOBILIARIO | E18: =$C$6 -> 2282.7 | F18: 16 | G18: =$E$18/$F$18 -> 142.66875 | H18: =$G$18/12 -> 11.889062
D19: EQUIPOS PARA EL PROCESO DE INFORMACIÓN | E19: =$C$7 -> 1095 | F19: 10 | G19: =$E$19/$F$19 -> 109.5 | H19: =$G$19/12 -> 9.125
D20: OTRO INMOVILIZADO MATERIAL | E20: =$C$8 -> 154.95 | F20: 5 | G20: =$E$20/$F$20 -> 30.99 | H20: =$G$20/12 -> 2.5825
D21: OTRAS INSTALACIONES | E21: =$C$9 -> 1332.97 | F21: 14 | G21: =$E$21/$F$21 -> 95.212143 | H21: =$G$21/12 -> 7.9343452
E22: Amortización material | G22: =SUM(G18:G21) -> 378.37089 | H22: =SUM(H18:H21) -> 31.530908
E25: CUOTA AMORTIZ. TOTAL ANUAL | G25: =SUM($G$15+$G$22) -> 490.62689

Sheet FACTURA M.M
D1: FACTURA
B2: El nombre de su empresa
B3: Dirección CALLE SOLSONES, 2 | D3: N.º DE FACTURA | E3: 87
B4: Ciudad, estado/provincia y código postal BARCELONA, 08820 | D4: FECHA | E4: 44562
B5: Teléfono 934 75 00 00
B6: correo electrónico bonificaciones@mediamarkt.es
D7: ENVIAR A
E8: Nombre ENIGMA ROOM, S.L
E9: Nombre de la empresa ENIGMA ROOM, S.L
E10: Dirección C/DOCTOR SALGADO
E11: Ciudad, estado/provincia y código postal Madrid, 28308
E12: Teléfono 925 15 25 15
B13: DESCRIPCIÓN | C13: Unidades | D13: P.Unitario | E13: TOTAL
B14: Ordenador portátil | C14: 3 | D14: 105 | E14: =IFERROR(DetallesDeFactura[[#This Row],[Unidades]]*DetallesDeFactura[[#This Row],[P.Unitario]], "") -> 315
B15: Televisor pantalla plana 75px | C15: 1 | D15: 350 | E15: =IFERROR(DetallesDeFactura[[#This Row],[Unidades]]*DetallesDeFactura[[#This Row],[P.Unitario]], "") -> 350
B16: Teléfono fijo | C16: 2 | D16: 70 | E16: =IFERROR(DetallesDeFactura[[#This Row],[Unidades]]*DetallesDeFactura[[#This Row],[P.Unitario]], "") -> 140
B17: Aire acondicionado MXC | C17: 3 | D17: 210.99 | E17: =IFERROR(DetallesDeFactura[[#This Row],[Unidades]]*DetallesDeFactura[[#This Row],[P.Unitario]], "") -> 632.97
B18: Alarma de seguridad | C18: 5 | D18: 140 | E18: =IFERROR(DetallesDeFactura[[#This Row],[Unidades]]*DetallesDeFactura[[#This Row],[P.Unitario]], "") -> 700
B19: Telefonillo | C19: 1 | D19: 55 | E19: =IFERROR(DetallesDeFactura[[#This Row],[Unidades]]*DetallesDeFactura[[#This Row],[P.Unitario]], "") -> 55
B20: Impresora | C20: 1 | D20: 250 | E20: =IFERROR(DetallesDeFactura[[#This Row],[Unidades]]*DetallesDeFactura[[#This Row],[P.Unitario]], "") -> 250
B21: Proyector | C21: 1 | D21: 180 | E21: =IFERROR(DetallesDeFactura[[#This Row],[Unidades]]*DetallesDeFactura[[#This Row],[P.Unitario]], "") -> 180
D22: SUBTOTAL | E22: =SUM(E14:E21) -> 2622.97
D23: I.V.A 21% | E23: =E22*0.21 -> 550.8237
D24: TOTAL | E24: =SUM(E22:E23) -> 3173.7937
B26: GRACIAS POR SU CONFIANZA

Sheet BALANCE
B3: Balance de situación final
B4: Nº cuenta | C4: ACTIVO | E4: Nº cuenta | F4: PATRIMONIO NETO Y PASIVO
C5: Activo No Corriente | F5: Patrimonio Neto
C6: INMOVILIZADO INTANGIBLE | E6: 100 | F6: Capital social | G6: =TESORERÍA!$C$44 -> 25000
A7: =D7-D8 -> 449.024 | B7: 206 | C7: Aplicaciones informáticas | D7: ='INVERSIÓN Y AMORT.'!$C$5 -> 561.28 | E7: 129 | F7: Resultado del ejercicio | G7: =Resultados!$Q$45 -> 25721.456
B8: 280 | C8: Amortización acumulada del inm. Intangible | D8: ='INVERSIÓN Y AMORT.'!$G$15 -> 112.256
C9: INMOVILIZADO MATERIAL
A10: ='INVERSIÓN Y AMORT.'!$C$9 -> 1332.97 | B10: 215 | C10: Otras instalaciones | D10: ='INVERSIÓN Y AMORT.'!$C$9 -> 1332.97
A11: ='INVERSIÓN Y AMORT.'!$C$6 -> 2282.7 | B11: 216 | C11: Mobiliario | D11: ='INVERSIÓN Y AMORT.'!$C$6 -> 2282.7
A12: ='INVERSIÓN Y AMORT.'!$C$7 -> 1095 | B12: 217 | C12: Equipos para procesos de la información | D12: ='INVERSIÓN Y AMORT.'!$C$7 -> 1095
A13: ='INVERSIÓN Y AMORT.'!$C$8 -> 154.95 | B13: 219 | C13: Otro inmovilizado material | D13: ='INVERSIÓN Y AMORT.'!$C$8 -> 154.95
B14: 281 | C14: Amortización acumulada del inm. Material | D14: ='INVERSIÓN Y AMORT.'!$G$22 -> 378.37089
A15: =SUM(A10:A13) -> 4865.62 | C15: TOTAL ACTIVO NO CORRIENTE | D15: =A7+A16 -> 4936.2731 | F15: TOTAL PATRIMONIO NETO | G15: =G6+G7 -> 50721.456
A16: =A15-D14 -> 4487.2491 | C16: Activo Corriente | F16: Pasivo Corriente
E17: 4750 | F17: H.Pública Acreedora por IVA | G17: ='I.V.A'!$I$26 -> 7421.8884
E18: 4751 | F18: HP Acreedora por retenciones practicadas | G18: =TESORERÍA!$L$31+TESORERÍA!L30 -> 3765
B19: 572 | C19: Banco | D19: =TESORERÍA!$N$56 -> 66595.229 | E19: 4752 | F19: HP Acreedora por Impuesto de Sociedades | G19: =Resultados!$P$45 -> 8573.8186
E20: 476 | F20: Organismos de la S.S, acreedores | G20: =TESORERÍA!D16 -> 1049.3396
C22: TOTAL ACTIVO CORRIENTE | D22: =SUM(D17:D19) -> 66595.229 | F22: TOTAL PASIVO CORRIENTE | G22: =SUM(G17:G20) -> 20810.047
C24: TOTAL ACTIVO | D24: =$D$15+$D$22 -> 71531.502 | F24: TOTAL PASIVO | G24: =G15+G22 -> 71531.502
G28: =G24-D24 -> 0
G29: 4456.8176

Sheet I.V.A
B3: PAGOS+B3:N7C3B3:B3:N7 | C3: I.V.A SOPORTADO
C4: 1 | D4: 2 | E4: 3 | F4: 1 | G4: 2 | H4: 3 | I4: 1 | J4: 2 | K4: 3 | L4: 1 | M4: 2 | N4: 3
C5: ENERO | D5: FEBRERO | E5: MARZO | F5: ABRIL | G5: MAYO | H5: JUNIO | I5: JULIO | J5: AGOSTO | K5: SEPTIEMBRE | L5: OCTUBRE | M5: NOVIEMBRE | N5: DICIEMBRE
B6: I.V.A SOPORTADO | C6: =TESORERÍA!C35+TESORERÍA!C36 -> 2194.7016 | D6: =TESORERÍA!D35+TESORERÍA!D36 -> 1095.4336 | E6: =TESORERÍA!E35+TESORERÍA!E36 -> 1055.0526 | F6: =TESORERÍA!F35+TESORERÍA!F36 -> 1095.4336 | G6: =TESORERÍA!G35+TESORERÍA!G36 -> 1055.0526 | H6: =TESORERÍA!H35+TESORERÍA!H36 -> 1095.4336 | I6: =TESORERÍA!I35+TESORERÍA!I36 -> 1055.0526 | J6: =TESORERÍA!J35+TESORERÍA!J36 -> 1095.4336 | ... N6: =TESORERÍA!N35+TESORERÍA!N36 -> 1095.4336
B7: I.V.A TRIMESTRAL | C7: =IF(C4=3,C6+D6+E6,"") | D7: =IF(D4=3,D6+E6+F6,"") | E7: =IF(E4=3,$C$6+$D$6+$E$6,"") -> 4345.1878 | F7: =IF(F4=3,F6+G6+H6,"") | G7: =IF(G4=3,G6+H6+I6,"") | H7: =IF(H4=3,$F$6+$G$6+$H$6,"") -> 3245.9198 | I7: =IF(I4=3,I6+J6+K6,"") | J7: =IF(J4=3,J6+K6+L6,"") | K7: =IF(K4=3,$I$6+$J$6+$K$6,"") -> 3205.5388 | L7: =IF(L4=3,L6+M6+N6,"") | M7: =IF(M4=3,M6+N6+O6,"") | N7: =IF(N4=3,$L$6+$M$6+$N$6,"") -> 3245.9198
B10: PAGOS+B3:N7C3B3:B3:N7 | C10: I.V.A REPERCUTIDO
C11: 1 | D11: 2 | E11: 3 | F11: 1 | G11: 2 | H11: 3 | I11: 1 | J11: 2 | K11: 3 | L11: 1 | M11: 2 | N11: 3
C12: ENERO | D12: FEBRERO | E12: MARZO | F12: ABRIL | G12: MAYO | H12: JUNIO | I12: JULIO | J12: AGOSTO | K12: SEPTIEMBRE | L12: OCTUBRE | M12: NOVIEMBRE | N12: DICIEMBRE
B13: I.V.A REPERCUTIDO | C13: =TESORERÍA!C48 -> 3462.9553 | D13: =TESORERÍA!D48 -> 3284.8194 | E13: =TESORERÍA!E48 -> 3692.9815 | F13: =TESORERÍA!F48 -> 3701.4975 | G13: =TESORERÍA!G48 -> 3878.6022 | H13: =TESORERÍA!H48 -> 3263.5226 | I13: =TESORERÍA!I48 -> 3793.2731 | J13: =TESORERÍA!J48 -> 3875.2561 | ... N13: =TESORERÍA!N48 -> 3668.7285
B14: I.V.A TRIMESTRAL | C14: =IF(C11=3,C13+D13+E13,"") | D14: =IF(D11=3,D13+E13+F13,"") | E14: =IF(E11=3,$C$13+$D$13+$E$13,"") -> 10440.756 | F14: =IF(F11=3,F13+G13+H13,"") | G14: =IF(G11=3,G13+H13+I13,"") | H14: =IF(H11=3,$F$13+$G$13+$H$13,"") -> 10843.622 | I14: =IF(I11=3,I13+J13+K13,"") | J14: =IF(J11=3,J13+K13+L13,"") | K14: =IF(K11=3,$I$13+$J$13+$K$13,"") -> 11470.262 | L14: =IF(L11=3,L13+M13+N13,"") | M14: =IF(M11=3,M13+N13+O13,"") | N14: =IF(N11=3,+$L$13+$M$13+$N$13,"") -> 10667.808
C22: 1º TRIMESTRE | E22: 2º TRIMESTRE | G22: 3º TRIMESTRE | I22: 4º TRIMESTRE
C23: I.V.A SOP | D23: I.V.A REP | E23: I.V.A SOP | F23: I.V.A REP | G23: I.V.A SOP | H23: I.V.A REP | I23: I.V.A SOP | J23: I.V.A REP
C24: =$E$7 -> 4345.1878 | D24: =$E$14 -> 10440.756 | E24: =$H$7 -> 3245.9198 | F24: =$H$14 -> 10843.622 | G24: =$K$7 -> 3205.5388 | H24: =$K$14 -> 11470.262 | I24: =$N$7 -> 3245.9198 | J24: =$N$14 -> 10667.808
B26: DIFERENCIA | C26: =D24-C24 -> 6095.5684 | E26: =F24-E24 -> 7597.7025 | G26: =H24-G24 -> 8264.7235 | I26: =J24-I24 -> 7421.8884

Sheet RATIOS
B3: FONDO DE MANIOBRA | D3: AC - PC | F3: =BALANCE!D22-BALANCE!G22 -> 45785.183 | G3: Esta es la cantidad de los recursos financieros a largo plazo de los que dispone la empresa para realizar su actividad en el corto plazo.
B7: RATIO DE DISPONIBILIDAD | D7: Disponible | F7: =BALANCE!$D$19/BALANCE!$G$22 -> 3.200148 | G7: Mide la capacidad que tiene la empresa a través de su disponible para hacer frente al exigible a corto plazo. Lo normal es que sea 0,1 (10%) [menor que 0,05-> escasez de disponibilidad] [ entre 0,05 y 0.09= ] [ >0,10=exceso de disp..].
D9: Exigible C.P
B12: RATIO DE TESORERÍA | D12: D + R | F12: =(BALANCE!$D$22+BALANCE!G17)/BALANCE!$G$22 -> 3.5567973 | G12: Permite medir la capacidad de una compañía o institución para pagar las deudas que vencen en el corto plazo. Como nuestra empresa presenta un ratio superior a 1, significa que puede hacer frente a las deudas inferiores a 1 año (a corto plazo).
D13: Exigible C.P
B16: RATIO DE LIQUIDEZ | D16: D+R+E | F16: =BALANCE!$D$22/BALANCE!$G$22 -> 3.200148 | G16: Éste refleja qué porcentaje de la deuda a corto plazo puede pagarse con los activos a corto plazo de la compañía. En nuestro caso es superior a 1 por lo que nos encontramos en una situación favorable.
D17: Exigible C.P
B20: RATIO DE GARANTÍA | D20: [D+R+E]+I | F20: =BALANCE!$D$24/BALANCE!$G$24 -> 1 | G20: Éste acredita la garantía que las empresas ofrecen a sus acreedores para hacer frente a sus obligaciones de pago. El resultado tiene que ser el activo > que la unidad y el que hemos obtenido nosotros es de 1 por lo que nuestra empresa se podría situar cerca de la quiebra.
D22: Exigible total
B25: RATIO DE ENDEUDAMIENTO | D25: PASIVO | F25: =BALANCE!$G$22/BALANCE!$G$15 -> 0.41028094 | G25: Éste representa qué parte de los activos de una empresa se financia mediante deuda. En nuestro caso es 0,41.
D26: P.N
B29: RATIO DE AUTONOMÍA FINANCIERA | D29: P.N | F29: =BALANCE!$G$15/BALANCE!$G$22 -> 2.4373543 | G29: Refleja la relación entre el capital propio y el conjunto de capitales permanentes. Este ratio debe ser igual o superior a 2, en nuestro caso esta regla se cumple por lo que la empresa puede hacer frente de sobra a los pagos a largo plazo.
D31: PASIVO
B34: RATIO RENTABILIDAD ECONÓMICA | D34: Bº | E34: X VENTAS | F34: =(BALANCE!$G$7/BALANCE!$D$24)*100 -> 35.958221 | G34: Este ratio permite conocer i el crecimiento de una compañía está acompañado de una mejora o deterioro del resultado, cuanto más alto sea este valor mejor para la empresa. El Bº/ ventas refleja el margen (si tienes mayor margen, la competencia lo agradece). Las ventas/activo reflejan la rotación (las empresas tratan de tener mayor margen de rotación, es decir, aumentar las ventas) Con poco margen de beneficio y mayor rotación (ventas) los actuales competidores y nuevos lo tienen complicado además, esto provoca que tengamos mayor beneficio durante muchos años.
D38: VENTAS | E38: ACTIVO
B43: RATIO RENTABILIDAD FINANCIERA | D43: Bº NETO | F43: =(Resultados!$Q$45/BALANCE!$G$15)*100 -> 50.711194 | G43: Cuanto más alto sea, mayores serán los beneficios obtenidos por los inversores. En nuestro caso es el 50,71%.
D44: P.Neto

Sheet factura trámite
E2: Fecha: | F2: 44562
B3: Dirección: | E3: Nº FACTURA: | F3: 135
C4: Dirección
C5: Ciudad, estado y código postal
C6: Teléfono:
B7: Extracto
E9: Factura para: | F9: Nombre ENIGMA ROOM, S.L
F10: Nombre de la empresa ENIGMA ROOM, S.L
F11: Dirección C/DOCTOR SALGADO
F12: Teléfono 925 15 25 15
B14: DESCRIPCIÓN | E14: PRECIO
B15: Pago del trámite para la copnstiutución de una empresa | E15: 350
D16: Base imponible | E16: =E15 -> 350
D17: I.V.A 21% | E17: =E16*0.21 -> 73.5
D18: TOTAL | E18: =E16+E17 -> 423.5
B20: Aviso: Incluya el número del extracto en el cheque.
B21: Condiciones: Saldo a pagar en 30 días.

Sheet FACTURA NOTARÍA
B2: Nombre: NOTARÍA ORENSE 8
B3: Dirección C/DOCTOR SALGADO | C3: FECHA: | D3: 44562
B4: Ciudad, código postal MADRID 28038 | C4: Nº FACTURA: | D4: 159
B5: Teléfono | Fax 921 24 52 55
B6: FACTURAR A:
B7: Nombre ENIGMA ROOM, S.L
B8: Nombre de la empresa ENIGMA ROOM, S.L
B9: Dirección C/DOCTOR SALGADO
B10: Ciudad, código postal MADRID 28038
B11: Teléfono 925 15 25 15
B12: DESCRIPCIÓN | C12: CANTIDAD
B13: Servicio profesional asesoría | C13: 105.8
B14: Base imponible | C14: =C13 -> 105.8
B15: I.V.A 21% | C15: =C14*0.21 -> 22.218
B16: TOTAL | C16: =C14+C15 -> 128.018
B20: ="Todos los cheques se extenderán a nombre de "&Company_Name&"." -> Todos los cheques se extenderán a nombre de .
B21: Total a pagar en 15 días. Cuentas vencidas sujetas a un cargo por servicios de 1% al mes.
B22: GRACIAS POR SU CONFIANZA

Sheet TALLER
C1: Nombre de la empresa: | D1: ENIGMA ROOM, S.L | E1: Fecha del extracto: | F1: 44562
C2: Dirección de la empresa: | D2: C/DOCTOR SALGADO | E2: Nº factura | F2: 97
C3: Ciudad, estado/provincia y código postal: | D3: MADRID 28038
C4: Teléfono: | D4: 925 15 25 15
C5: EXTRACTO DE LA CUENTA
C6: Nombre del cliente
C7: Dirección
C8: Ciudad y código postal
C9: DESCRIPCIÓN | D9: CANTIDAD | E9: Precio unitario | F9: TOTAL
C10: Revisión total del vehículo | D10: 9 | E10: 65 | F10: =D10*E10 -> 585
E11: Base imponible | F11: =F10 -> 585
E12: I.V.A 21% | F12: =F11*0.21 -> 122.85
E13: TOTAL | F13: =SUM(F11:F12) -> 707.85

Sheet FACTURA AGUA
B1: Elabore una factura de servicio sencilla en esta hoja de cálculo. Encontrará instrucciones útiles sobre cómo usar esta hoja de cálculo en las celdas de esta columna. Presione la flecha de abajo para empezar.
B2: Pegue el logotipo de la empresa en la celda de la derecha. El título de esta hoja de cálculo está en la celda D2. | C2: El marcador del logotipo se encuentra en esta celda. | E2: Factura
B3: Escriba el nombre de la empresa en la celda de la derecha y la fecha en la celda E3. | C3: El nombre de su empresa | E3: Fecha: | F3: 44562
B4: Escriba el eslogan de la empresa en la celda de la derecha y el número de factura en la celda E4. | E4: N.º de factura: | F4: N.º16
B5: Escriba el Id. de cliente en la celda E5.
B6: La etiqueta Para se encuentra en la celda de la derecha. Escriba datos de facturación como nombre, nombre de la compañía, dirección y número de teléfono en las celdas C6 a C10. La instrucción siguiente se encuentra en la celda A11. | C6: Para: | D6: Nombre ENIGMA ROOM, S.L
D7: Nombre de la empresa ENIGMA ROOM, S.L
D8: Dirección C/Doctor Salgado
D9: Ciudad y código postal MADRID 28038
D10: Teléfono 925 15 25 15
B12: Escriba la información en la tabla Factura que comienza en la celda de la derecha. El total y el subtotal se calculan automáticamente. La instrucción siguiente se encuentra en la celda A40.
C15: CONCEPTO | D15: IMPORTE SIN IVA (10%) | E15: Columna1 | F15: Columna2
C16: ADUCCIÓN | D16: 40.05
C17: DISTRIBUCIÓN | D17: 30.7
C18: DEPURACIÓN | D18: 20
C19: ALCANTARILLADO | D19: 12.65
C21: Base imponible | D21: =SUM(D16:D19) -> 103.4 | E21: IMPORTE I.V.A | F21: =(Tabla1[[#This Row],[IMPORTE SIN IVA (10%)]]*0.1) -> 10.34
C23: TOTAL FACTURA (I.V.A incluido) | D23: =SUM(D21,F21) -> 113.74
B36: El nombre de la compañía se actualiza automáticamente en la celda D40.
B37: El mensaje de agradecimiento está en la celda de la derecha.
B38: Escriba la dirección de la empresa, la ciudad, provincia, código postal, números de teléfono y fax, y dirección de correo electrónico en la celda de la derecha.

Sheet Cálculos Nómina
B4: Nóminas | C4: Sueldo bruto | D4: S.S. c/t | E4: IRPF | F4: Sueldo neto
B5: =Nóminas!$P$80&" (socia)" -> Laura García Peña (socia) | C5: =Nóminas!$T$115 -> 1725 | D5: =Nóminas!$P$124 -> 0 | E5: =Nóminas!$P$125 -> 100 | F5: =$C$5-$E$5 -> 1625
B6: =Nóminas!$P$2&" (socia)" -> Brenda Fernández Sánchez (socia) | C6: =Nóminas!$T$37 -> 3000.5 | D6: =Nóminas!$P$46 -> 0 | E6: =Nóminas!$P$203 -> 100 | F6: =$C$6-E6 -> 2900.5
B7: =Nóminas!$P$158&" (trabajador)" -> Mar López Pérez (trabajador) | C7: =Nóminas!$T$193 -> 1495 | D7: =Nóminas!$P$202 -> 94.9325 | E7: =Nóminas!$P$283 -> 100 | F7: =C7-D7-E7 -> 1300.0675
B8: =Nóminas!$P$238&" (trabajador)" -> Marcos Rodríguez López (trabajador) | C8: =Nóminas!$T$273 -> 1470 | D8: =Nóminas!$P$282 -> 93.345 | E8: =Nóminas!$P$283 -> 100 | F8: =C8-D8-E8 -> 1276.655
B10: TOTAL | C10: =SUM(C5:C8) -> 7690.5 | D10: =SUM(D7:D8) -> 188.2775 | E10: =SUM(E5:E8) -> 400 | F10: =SUM(F5:F8) -> 7102.2225
B13: Cuota Seguridad Social
B14: Trabajador | C14: S.S c/e | D14: seguridad social trabajdor | E14: Total
B15: =Nóminas!$P$80&" (socia)" -> Laura García Peña (socia) | C15: =Nóminas!$R$152 -> 192.40208 | D15: =Nóminas!$P$124 -> 0 | E15: =SUM(C15,D15) -> 192.40208
B16: =Nóminas!$P$2&" (socia)" -> Brenda Fernández Sánchez (socia) | C16: =Nóminas!$R$74 -> 331.02556 | D16: =Nóminas!$P$46 -> 0 | E16: =SUM(C16,D16) -> 331.02556
B17: =Nóminas!$P$158&" (trabajador)" -> Mar López Pérez (trabajador) | C17: =Nóminas!$R$230 -> 169.02158 | D17: =D7 -> 94.9325 | E17: =SUM(C17,D17) -> 263.95408
B18: =Nóminas!$P$238&" (trabajador)" -> Marcos Rodríguez López (trabajador) | C18: =Nóminas!$R$310 -> 168.61283 | D18: =D8 -> 93.345 | E18: =SUM(C18,D18) -> 261.95783
B20: TOTAL | C20: =SUM(C15:C18) -> 861.06206 | D20: =SUM(D15:D18) -> 188.2775 | E20: =SUM(E15:E18) -> 1049.3396
B23: Cuota Autónomo Seguridad Social
B24: Socio | C24: Tipo cuota | D24: Importe
B25: =Nóminas!$P$80&" (socia)" -> Laura García Peña (socia) | C25: RETA | D25: =C15 -> 192.40208
B26: =Nóminas!$P$2&" (socia)" -> Brenda Fernández Sánchez (socia) | C26: RETA | D26: =C16 -> 331.02556
B28: TOTAL | C28: =SUM(D25:D26) -> 523.42764

Sheet FACTURA IKEA
B1: FACTURA
B4: Dirección Avenida Matapiñonera, 9 | C4: N.º DE FACTURA | D4: 102
B5: Ciudad, provincia y código postal 28708, MADRID | C5: FECHA | D5: 44562
B6: Teléfono | Fax 910378769 | C6: ID. DEL CLIENTE | D6: ABC12345
B7: Correo electrónico so.contabilidad.rg.es@ikea.com
C9: ENVIAR A
C10: Nombre | D10: ENIGMA ROOM, S.L
C11: Nombre de la empresa ENIGMA ROOM, S.L
C12: Dirección | D12: Doctor Salgado Nº16
C13: Ciudad, provincia y código postal | E13: Madrid, 28038
C14: Teléfono | D14: 918 15 25 35
B15: DESCRIPCIÓN DE CARGO FINANCIERO | C15: UNIDADES | D15: P.Unitario | E15: TOTAL
B16: Cubo de basura | C16: 3 | D16: 5.9 | E16: =Factura[[#This Row],[UNIDADES]]*Factura[[#This Row],[P.Unitario]] -> 17.7
B17: Escritorio de madera | C17: 4 | D17: 105 | E17: =Factura[[#This Row],[UNIDADES]]*Factura[[#This Row],[P.Unitario]] -> 420
B18: Juguetes de bebé | C18: 7 | D18: 6 | E18: =Factura[[#This Row],[UNIDADES]]*Factura[[#This Row],[P.Unitario]] -> 42
B19: Mini sofá | C19: 2 | D19: 20 | E19: =Factura[[#This Row],[UNIDADES]]*Factura[[#This Row],[P.Unitario]] -> 40
B20: Silla de oficina | C20: 2 | D20: 22 | E20: =Factura[[#This Row],[UNIDADES]]*Factura[[#This Row],[P.Unitario]] -> 44
B21: Estufa de leña de pie | C21: 1 | D21: 85 | E21: =Factura[[#This Row],[UNIDADES]]*Factura[[#This Row],[P.Unitario]] -> 85
B22: Cuna de bebé | C22: 1 | D22: 40 | E22: =Factura[[#This Row],[UNIDADES]]*Factura[[#This Row],[P.Unitario]] -> 40
B23: Estantería francés | C23: 2 | D23: 37 | E23: =Factura[[#This Row],[UNIDADES]]*Factura[[#This Row],[P.Unitario]] -> 74
B24: Escalera | C24: 1 | D24: 36 | E24: =Factura[[#This Row],[UNIDADES]]*Factura[[#This Row],[P.Unitario]] -> 36
B25: Baúl | C25: 6 | D25: 76 | E25: =Factura[[#This Row],[UNIDADES]]*Factura[[#This Row],[P.Unitario]] -> 456
B26: Lavabo | C26: 1 | D26: 55 | E26: =Factura[[#This Row],[UNIDADES]]*Factura[[#This Row],[P.Unitario]] -> 55
B27: Lámpara #45 | C27: 2 | D27: 19 | E27: =Factura[[#This Row],[UNIDADES]]*Factura[[#This Row],[P.Unitario]] -> 38
... B37: Cuadros | C37: 7 | D37: 12 | E37: =Factura[[#This Row],[UNIDADES]]*Factura[[#This Row],[P.Unitario]] -> 84
D38: SUBTOTAL | E38: =SUM(Factura[TOTAL]) -> 2282.7 | G38: 2282.7
D39: I.V.A 21% | E39: =E38*0.21 -> 479.367
D40: TOTAL | E40: =SUM(E38+E39) -> 2762.067 | G40: 2762.067

Sheet FACTURA LUZ 
C2: FECHA: | D2: 44562
C3: N. º DE FACTURA | D3: 105
C4: FACTURAR A: | D4: Nombre | E4: ENIGMA ROOM, S.L
B5: Dirección | D5: Nombre de la empresa | E5: ENIGMA ROOM, S.L
B6: Ciudad y código postal | D6: Dirección | E6: C/DOCTOR SALGADO
B7: Teléfono | D7: Ciudad y código postal | E7: Madrid, 28308
B8: Fax | D8: Teléfono | E8: 925 15 25 15
B9: Descripción del proyecto o servicio
B10: RESUMEN DE FACTURACION | D10: IMPORTE
B11: ENERGIA | D11: 198.72
B12: SERVIO Y OTROS CONCEPTOS | D12: =46.83+24.3 -> 71.13
C13: SUBTOTAL | D13: =SUM(D11:D12) -> 269.85
C14: TASA DE IMPUESTO | D14: =('FACTURA LUZ '!$D$13*0.21) -> 56.6685
C15: TOTAL | D15: =('FACTURA LUZ '!$D$13+D14) -> 326.5185
B18: GRACIAS POR SU CONFIANZA

Sheet FACTURA GAS
C2: FECHA: | D2: 44562
C3: N. º DE FACTURA | D3: 105
C4: FACTURAR A: | D4: Nombre | E4: ENIGMA ROOM, S.L
B5: Dirección | D5: Nombre de la empresa | E5: ENIGMA ROOM, S.L
B6: Ciudad y código postal | D6: Dirección | E6: C/DOCTOR SALGADO
B7: Teléfono | D7: Ciudad y código postal | E7: Madrid, 28308
B8: Fax | D8: Teléfono | E8: 925 15 25 15
B9: Descripción del proyecto o servicio
B10: RESUMEN DE FACTURACION | D10: IMPORTE
B11: ENERGIA | D11: 99.11
B12: SERVIO Y OTROS CONCEPTOS | D12: 34.85
C13: SUBTOTAL | D13: =SUM(D11:D12) -> 133.96
C14: TASA DE IMPUESTO | D14: =('FACTURA GAS'!$D$13*0.21) -> 28.1316
C15: TOTAL | D15: =('FACTURA GAS'!$D$13+D14) -> 162.0916
B17: GRACIAS POR SU CONFIANZA

Sheet ALQUILER LOCAL
C1: FACTURA
B3: Dirección | D3: FECHA: | E3: 44562
B4: Ciudad, código postal | D4: N.º DE FACTURA | E4: 78
B5: Teléfono | Fax
B6: FACTURAR A:
B7: Nombre ENIGMA ROOM, S.L
B8: Nombre de la empresa ENIGMA ROOM, S.L
B9: Dirección C/DOCTOR SALGADO
B10: Ciudad, código postal MADRID, 28038
B11: Teléfono 925 21 51 2 4
B12: DESCRIPCIÓN | C12: PRECIO
B13: Alquiler local 260m2 | C13: 4500
B15: BASE IMPONIBLE | C15: =C13 -> 4500
B16: IVA del 21% | C16: =0.21*C13 -> 945
B17: Retención 19% | C17: =0.19*C15 -> 855
B18: TOTAL | C18: =(C13+C16)-(C17) -> 4590

Sheet FACTURA VODAFONE
C1: FACTURA
B3: Dirección Avenida de América, 115 | C3: FECHA: | D3: 44562
B4: Ciudad, estado/provincia y código postal Madrid 28042 | C4: N.º DE FACTURA | D4: 87
B5: [Número de] teléfono 921564564
B6: Facturar a:
B7: Nombre ENIGMA ROOM, S.L
B8: Nombre de la empresa ENIGMA ROOM, S.L
B9: Dirección C/DOCTOR SALGADO
B10: Ciudad, estado/provincia y código postal MADRID, 28308
B11: Teléfono 925 15 25 15
B12: DESCRIPCIÓN | D12: IMPORTE
B13: Llamadas y videollamadas | D13: 21.8
B14: Mensajes | D14: 18
B15: Conexiones lived y datos | D15: 80.45
B16: TOTAL | D16: =SUM(D13:D15) -> 120.25
B17: IVA 21% | D17: =D16*0.21 -> 25.2525
C18: TOTAL A PAGAR | D18: =D16+D17 -> 145.5025
B19: ="Establezca que todos los cheques se paguen a "&Nombre_empresa&"" -> Establezca que todos los cheques se paguen a
B20: Si tiene cualquier tipo de pregunta acerca de esta factura, póngase en contacto con Nombre, Número de teléfono o Correo electrónico
B21: GRACIAS POR SU CONFIANZA

Sheet FACTURA AMAZON
B1: Factura
B2: El nombre de su empresa | C2: Fecha | D2: 44562
B3: Dirección
B4: Ciudad, estado/provincia y código postal
B5: Teléfono
B7: Facturar a:
B8: Nombre ENIGMA ROOM, S.L
B9: Nombre de la empresa ENIGMA ROOM, S.L
B10: Dirección C/DOCTOR SALGADO
B11: Ciudad, estado/provincia y código postal MADRID, 28038
B12: Teléfono 925 15 25 15
B14: DESCRIPCIÓN | C14: IMPORTE
B15: Smartwares Extintor de Polvo Seco, 1 KG, Resistencia al Fuego ABC | C15: 14.95
B16: Programa Contabilidad Profesional de Aplifisa | C16: 210.5
B17: Equipo de RV (Realidad Virtual) | C17: 450
B18: Microsoft 365 Empresa Estándar | C18: 350.78
B21: BASE IMPONIBLE | C21: =SUM(C15:C18) -> 1026.23
B22: I.V.A 21% | C22: =C21*0.21 -> 215.5083
B23: TOTAL | C23: =C21+C22 -> 1241.7383
B24: GRACIAS POR SU CONFIANZA

Sheet Nóminas
B2: Empresa: | F2: ENIGMA ROOM, S.L. | O2: Trabajador: | P2: Brenda Fernández Sánchez
B3: Domicilio: | F3: C/Doctor Salgado | O3: NIF: | P3: 02548658P
B4: Localidad: | F4: Madrid | O4: NAF: | P4: 446565879147
B5: CIF: | F5: B45123452 | O5: Grupo Profesional | Q5: ingeniero y licenciados
B6: CCC a la SS: | F6: 1234567892 | O6: Grupo Cotiz.: | P6: 1
B9: Periodo de Liquidación: | G9: del | H9: 2 | I9: de | J9: enero | K9: al | L9: 31 | N9: de | O9: enero | P9: de | Q9: 2022 | R9: Total días: | T9: 30
C12: I. | D12: DEVENGOS | P12: IMPORTE | T12: TOTALES
C13: 1.- | D13: Percepciones Salariales (Sujetas a cotización)
D14: Salario Base................................................................................................ | P14: 2850.5
D15: Complentos Salariales:
O16: ....................
O17: ....................
O18: ....................
D19: Horas Extras Fuerza Mayor...........................................................................
D20: Horas Extras Resto........................................................................................
D21: Horas Complementarias (contratos a tiempo parcial)..................................
D22: Gratificaciones extraordinarias...................................................................... | P22: 150
D23: Salario en especie.........................................................................................
C25: 2.- | D25: Percepciones no salariales (Excluidas de cotización)
D26: Indemnizaciones o suplidos:
O27: ....................
O28: ....................
O29: ....................
D30: Prestaciones e indemnizaciones de la Seguridad Social:
O31: ....................
D32: Indemnizaciones por traslados, suspensiones o despidos:
O33: ....................
D34: Otras percepciones salariales:
O35: ....................
J37: A.- TOTAL DEVENGADO................................................ | T37: =P14+P22 -> 3000.5
C39: II.- | D39: DEDUCCIONES
D40: 1. | E40: Aportaciones del trabajador a las cotizaciones a la S.S. Y conceptos de recaudación conjunta:
E41: Contingencias Comunes......................................... | K41: 0 | L41: % | N41: 0
E42: Desempleo................................................................. | K42: 0 | L42: % | N42: 0
E43: Formación Profesional............................................ | K43: 0 | L43: % | N43: 0
E44: Horas Extras Fuerza Mayor................................... | K44: 0 | L44: % | N44: 0
E45: Horas Extras Resto.................................................. | K45: 0 | L45: % | N45: 0
F46: TOTAL APORTACIONES............................................................................. | P46: =SUM(N41:O45) -> 0
D47: 2. | E47: Impuesto sobre la Renta de las Personas Fisicas | K47: 10 | L47: % | M47: ........................ | P47: 100
D48: 3.- | E48: Anticipos.........................................................................................................................
...

Sheet Póliza de seguro
B3: Dirección C. de Emilio Vargas, 6 | C3: Fecha: | D3: 44562
B4: Ciudad, código postal 28043 Madrid | C4: Nº factura: | D4: 165
B5: Teléfono | Fax 902 40 40 84
B6: FACTURAR A:
B7: Nombre ENIGMA ROOM, S.L
B8: Nombre de la empresa ENIGMA ROOM, S.L
B9: Dirección C/DOCTOR SALGADO
B10: Ciudad, código postal MADRID, 28038
B11: Teléfono 925 15 25 15
B13: DESCRIPCIÓN | C13: CANTIDAD
B14: Póliza de seguro cobertuta total | C14: 615.3
C15: =IFERROR(#REF!*#REF!, "")
C16: =IFERROR(#REF!+#REF!+#REF!, "")
B17: TOTAL | C17: =SUM(C14) -> 615.3

Sheet SEGUROS SOCIALES
A3: SEGUROS SOCIALES
C4: CUOTA MENSUAL A PAGAR
A5: BASE DE COTIZACIÓN | C5: 960.6
A6: SEGURIDAD SOCIAL (28,30%) | C6: =0.283*$C$5 -> 271.8498
A7: TOTAL | C7: =$C$6 -> 271.8498
A8: NÚMERO DE SOCIOS ADMINISTRADORES | C8: 2
A9: CUOTA A INGRESAR EN LA SEGURIDAD SOCIAL | C9: =C7*C8 -> 543.6996
